Traceback (most recent call last):
  File "/Users/Sam/miniconda3/lib/python3.10/site-packages/jupyter_cache/executors/utils.py", line 58, in single_nb_execution
    executenb(
  File "/Users/Sam/miniconda3/lib/python3.10/site-packages/nbclient/client.py", line 1204, in execute
    return NotebookClient(nb=nb, resources=resources, km=km, **kwargs).execute()
  File "/Users/Sam/miniconda3/lib/python3.10/site-packages/nbclient/util.py", line 84, in wrapped
    return just_run(coro(*args, **kwargs))
  File "/Users/Sam/miniconda3/lib/python3.10/site-packages/nbclient/util.py", line 62, in just_run
    return loop.run_until_complete(coro)
  File "/Users/Sam/miniconda3/lib/python3.10/asyncio/base_events.py", line 649, in run_until_complete
    return future.result()
  File "/Users/Sam/miniconda3/lib/python3.10/site-packages/nbclient/client.py", line 663, in async_execute
    await self.async_execute_cell(
  File "/Users/Sam/miniconda3/lib/python3.10/site-packages/nbclient/client.py", line 965, in async_execute_cell
    await self._check_raise_for_error(cell, cell_index, exec_reply)
  File "/Users/Sam/miniconda3/lib/python3.10/site-packages/nbclient/client.py", line 862, in _check_raise_for_error
    raise CellExecutionError.from_cell_and_msg(cell, exec_reply_content)
nbclient.exceptions.CellExecutionError: An error occurred while executing the following cell:
------------------
source('../tests/tests.R')
------------------

[1m[33mError[39m in `reporter$stop_if_needed()`:[22m
[33m![39m Test failed
Traceback:

1. source("../tests/tests.R")
2. withVisible(eval(ei, envir))
3. eval(ei, envir)
4. eval(ei, envir)
5. test_that("X-axis label is not the same!", {
 .     majority_classifier <- read_csv("../data/modelling/majority_classifier.csv")
 .     plot <- majority_classifier_vis_function(majority_classifier)
 .     expect_identical(plot$labels$x, "Heart disease degree of severity")
 . })
6. (function (envir) 
 . {
 .     handlers <- get_handlers(envir)
 .     errors <- list()
 .     for (handler in handlers) {
 .         tryCatch(eval(handler$expr, handler$envir), error = function(e) {
 .             errors[[length(errors) + 1]] <<- e
 .         })
 .     }
 .     attr(envir, "withr_handlers") <- NULL
 .     for (error in errors) {
 .         stop(error)
 .     }
 . })(<environment>)
ERROR: [1m[33mError[39m in `reporter$stop_if_needed()`:[22m
[33m![39m Test failed


